Workbook

Sheet Exchange Rate
A1: KEN JP ANIME FIGURES SHOP — EXCHANGE RATE REGISTRY
A4: PHP → JPY BASE RATE | D4: JPY → PHP BASE RATE
A5: 1 PHP equals (JPY): | B5: 2.7 | D5: 1 JPY equals (PHP): | E5: 0.37
A6: ▸ Used in Col G: Selling Price (JPY) = Col F × this rate | D6: ▸ Used in Col E: Purchase Price (PHP) = Col D × this rate
A8: ⚠️ HOW TO USE THIS SHEET — READ CAREFULLY
A9: ▸ Edit ONLY the yellow cells: B5 (PHP→JPY) and E5 (JPY→PHP).
A10: ▸ All 8 tracking sheets reference these cells directly via formula.
A11: ▸ Changing a rate here instantly recalculates every currency conversion in the workbook.
A12: ▸ Do NOT rename this sheet — it is referenced by the exact name 'Exchange Rate'.
A13: ▸ Do NOT move B5 or E5 — all inventory formulas point to these locked absolute addresses.

Sheet 1. Anime Figures
A1: KEN JP ANIME FIGURES SHOP
A4: 📦 1. ANIME FIGURES | Rates: 'Exchange Rate'!B5 (PHP→JPY) & E5 (JPY→PHP)
A5: 🔍 FUZZY SEARCH | B5: ⬇ type partial name or ID: | D5: =IF($C$5="","← type above",IFERROR(ROWS(filter($M$8:$M$107,ISNUMBER(SEARCH($C$5,$M$8:$M$107))))&" match(es) found","❌ 0 found")) -> ← type above | E5: View match #: | F5: 1 | G5: =IF($C$5="","— no active search —",IFERROR(INDEX(filter($M$8:$M$107,ISNUMBER(SEARCH($C$5,$M$8:$M$107)),"❌ No Data Found"),VALUE($F$5)),"❌ No Data Found")) -> — no active search — | H5: =IFERROR(IF($G$5="❌ No Data Found","—",IF($G$5="— no active search —","—",INDEX($D$8:$D$107,MATCH($G$5,$M$8:$M$107,0)))),"—") -> — | I5: =IFERROR(IF($G$5="❌ No Data Found","—",IF($G$5="— no active search —","—",INDEX($F$8:$F$107,MATCH($G$5,$M$8:$M$107,0)))),"—") -> — | J5: =IFERROR(IF($G$5="❌ No Data Found","—",IF($G$5="— no active search —","—",INDEX($H$8:$H$107,MATCH($G$5,$M$8:$M$107,0)))),"—") -> — | K5: =IFERROR(IF($G$5="❌ No Data Found","—",IF($G$5="— no active search —","—",INDEX($J$8:$J$107,MATCH($G$5,$M$8:$M$107,0)))),"—") -> — | L5: =IFERROR(IF($G$5="❌ No Data Found","—",IF($G$5="— no active search —","—",INDEX($L$8:$L$107,MATCH($G$5,$M$8:$M$107,0)))),"—") -> —
A7: Product ID | B7: Date of Entry | C7: Transaction Month | D7: Purchase Price (JPY) | E7: Purchase Price (PHP) | F7: Selling Price (PHP) | G7: Selling Price (JPY) | H7: Net Profit (JPY) | I7: Net Profit (PHP) | J7: Net Loss (JPY) | K7: Net Loss (PHP) | L7: Stock Status | M7: SEARCH_KEY (hidden)
C8: =IF(B8="","",TEXT(B8,"mmmm")) | E8: =IF(D8="","",D8*'Exchange Rate'!$E$5) | G8: =IF(F8="","",F8*'Exchange Rate'!$B$5) | H8: =IF(L8="Inactive",0,IF(ISNUMBER(G8)*ISNUMBER(D8),IF(G8>D8,G8-D8,0),0)) -> 0 | I8: =IF(L8="Inactive",0,IF(ISNUMBER(F8)*ISNUMBER(E8),IF(F8>E8,F8-E8,0),0)) -> 0 | J8: =IF(L8="Inactive",0,IF(ISNUMBER(D8)*ISNUMBER(G8),IF(D8>G8,D8-G8,0),0)) -> 0 | K8: =IF(L8="Inactive",0,IF(ISNUMBER(E8)*ISNUMBER(F8),IF(E8>F8,E8-F8,0),0)) -> 0 | L8: Active | M8: =IF(A8="","—",A8&" ("&TEXT(B8,"MM/DD/YYYY")&")") -> —
C9: =IF(B9="","",TEXT(B9,"mmmm")) | E9: =IF(D9="","",D9*'Exchange Rate'!$E$5) | G9: =IF(F9="","",F9*'Exchange Rate'!$B$5) | H9: =IF(L9="Inactive",0,IF(ISNUMBER(G9)*ISNUMBER(D9),IF(G9>D9,G9-D9,0),0)) -> 0 | I9: =IF(L9="Inactive",0,IF(ISNUMBER(F9)*ISNUMBER(E9),IF(F9>E9,F9-E9,0),0)) -> 0 | J9: =IF(L9="Inactive",0,IF(ISNUMBER(D9)*ISNUMBER(G9),IF(D9>G9,D9-G9,0),0)) -> 0 | K9: =IF(L9="Inactive",0,IF(ISNUMBER(E9)*ISNUMBER(F9),IF(E9>F9,E9-F9,0),0)) -> 0 | L9: Active | M9: =IF(A9="","—",A9&" ("&TEXT(B9,"MM/DD/YYYY")&")") -> —
C10: =IF(B10="","",TEXT(B10,"mmmm")) | E10: =IF(D10="","",D10*'Exchange Rate'!$E$5) | G10: =IF(F10="","",F10*'Exchange Rate'!$B$5) | H10: =IF(L10="Inactive",0,IF(ISNUMBER(G10)*ISNUMBER(D10),IF(G10>D10,G10-D10,0),0)) -> 0 | I10: =IF(L10="Inactive",0,IF(ISNUMBER(F10)*ISNUMBER(E10),IF(F10>E10,F10-E10,0),0)) -> 0 | J10: =IF(L10="Inactive",0,IF(ISNUMBER(D10)*ISNUMBER(G10),IF(D10>G10,D10-G10,0),0)) -> 0 | K10: =IF(L10="Inactive",0,IF(ISNUMBER(E10)*ISNUMBER(F10),IF(E10>F10,E10-F10,0),0)) -> 0 | L10: Active | M10: =IF(A10="","—",A10&" ("&TEXT(B10,"MM/DD/YYYY")&")") -> —
C11: =IF(B11="","",TEXT(B11,"mmmm")) | E11: =IF(D11="","",D11*'Exchange Rate'!$E$5) | G11: =IF(F11="","",F11*'Exchange Rate'!$B$5) | H11: =IF(L11="Inactive",0,IF(ISNUMBER(G11)*ISNUMBER(D11),IF(G11>D11,G11-D11,0),0)) -> 0 | I11: =IF(L11="Inactive",0,IF(ISNUMBER(F11)*ISNUMBER(E11),IF(F11>E11,F11-E11,0),0)) -> 0 | J11: =IF(L11="Inactive",0,IF(ISNUMBER(D11)*ISNUMBER(G11),IF(D11>G11,D11-G11,0),0)) -> 0 | K11: =IF(L11="Inactive",0,IF(ISNUMBER(E11)*ISNUMBER(F11),IF(E11>F11,E11-F11,0),0)) -> 0 | L11: Active | M11: =IF(A11="","—",A11&" ("&TEXT(B11,"MM/DD/YYYY")&")") -> —
C12: =IF(B12="","",TEXT(B12,"mmmm")) | E12: =IF(D12="","",D12*'Exchange Rate'!$E$5) | G12: =IF(F12="","",F12*'Exchange Rate'!$B$5) | H12: =IF(L12="Inactive",0,IF(ISNUMBER(G12)*ISNUMBER(D12),IF(G12>D12,G12-D12,0),0)) -> 0 | I12: =IF(L12="Inactive",0,IF(ISNUMBER(F12)*ISNUMBER(E12),IF(F12>E12,F12-E12,0),0)) -> 0 | J12: =IF(L12="Inactive",0,IF(ISNUMBER(D12)*ISNUMBER(G12),IF(D12>G12,D12-G12,0),0)) -> 0 | K12: =IF(L12="Inactive",0,IF(ISNUMBER(E12)*ISNUMBER(F12),IF(E12>F12,E12-F12,0),0)) -> 0 | L12: Active | M12: =IF(A12="","—",A12&" ("&TEXT(B12,"MM/DD/YYYY")&")") -> —
C13: =IF(B13="","",TEXT(B13,"mmmm")) | E13: =IF(D13="","",D13*'Exchange Rate'!$E$5) | G13: =IF(F13="","",F13*'Exchange Rate'!$B$5) | H13: =IF(L13="Inactive",0,IF(ISNUMBER(G13)*ISNUMBER(D13),IF(G13>D13,G13-D13,0),0)) -> 0 | I13: =IF(L13="Inactive",0,IF(ISNUMBER(F13)*ISNUMBER(E13),IF(F13>E13,F13-E13,0),0)) -> 0 | J13: =IF(L13="Inactive",0,IF(ISNUMBER(D13)*ISNUMBER(G13),IF(D13>G13,D13-G13,0),0)) -> 0 | K13: =IF(L13="Inactive",0,IF(ISNUMBER(E13)*ISNUMBER(F13),IF(E13>F13,E13-F13,0),0)) -> 0 | L13: Active | M13: =IF(A13="","—",A13&" ("&TEXT(B13,"MM/DD/YYYY")&")") -> —
C14: =IF(B14="","",TEXT(B14,"mmmm")) | E14: =IF(D14="","",D14*'Exchange Rate'!$E$5) | G14: =IF(F14="","",F14*'Exchange Rate'!$B$5) | H14: =IF(L14="Inactive",0,IF(ISNUMBER(G14)*ISNUMBER(D14),IF(G14>D14,G14-D14,0),0)) -> 0 | I14: =IF(L14="Inactive",0,IF(ISNUMBER(F14)*ISNUMBER(E14),IF(F14>E14,F14-E14,0),0)) -> 0 | J14: =IF(L14="Inactive",0,IF(ISNUMBER(D14)*ISNUMBER(G14),IF(D14>G14,D14-G14,0),0)) -> 0 | K14: =IF(L14="Inactive",0,IF(ISNUMBER(E14)*ISNUMBER(F14),IF(E14>F14,E14-F14,0),0)) -> 0 | L14: Active | M14: =IF(A14="","—",A14&" ("&TEXT(B14,"MM/DD/YYYY")&")") -> —
C15: =IF(B15="","",TEXT(B15,"mmmm")) | E15: =IF(D15="","",D15*'Exchange Rate'!$E$5) | G15: =IF(F15="","",F15*'Exchange Rate'!$B$5) | H15: =IF(L15="Inactive",0,IF(ISNUMBER(G15)*ISNUMBER(D15),IF(G15>D15,G15-D15,0),0)) -> 0 | I15: =IF(L15="Inactive",0,IF(ISNUMBER(F15)*ISNUMBER(E15),IF(F15>E15,F15-E15,0),0)) -> 0 | J15: =IF(L15="Inactive",0,IF(ISNUMBER(D15)*ISNUMBER(G15),IF(D15>G15,D15-G15,0),0)) -> 0 | K15: =IF(L15="Inactive",0,IF(ISNUMBER(E15)*ISNUMBER(F15),IF(E15>F15,E15-F15,0),0)) -> 0 | L15: Active | M15: =IF(A15="","—",A15&" ("&TEXT(B15,"MM/DD/YYYY")&")") -> —
C16: =IF(B16="","",TEXT(B16,"mmmm")) | E16: =IF(D16="","",D16*'Exchange Rate'!$E$5) | G16: =IF(F16="","",F16*'Exchange Rate'!$B$5) | H16: =IF(L16="Inactive",0,IF(ISNUMBER(G16)*ISNUMBER(D16),IF(G16>D16,G16-D16,0),0)) -> 0 | I16: =IF(L16="Inactive",0,IF(ISNUMBER(F16)*ISNUMBER(E16),IF(F16>E16,F16-E16,0),0)) -> 0 | J16: =IF(L16="Inactive",0,IF(ISNUMBER(D16)*ISNUMBER(G16),IF(D16>G16,D16-G16,0),0)) -> 0 | K16: =IF(L16="Inactive",0,IF(ISNUMBER(E16)*ISNUMBER(F16),IF(E16>F16,E16-F16,0),0)) -> 0 | L16: Active | M16: =IF(A16="","—",A16&" ("&TEXT(B16,"MM/DD/YYYY")&")") -> —
C17: =IF(B17="","",TEXT(B17,"mmmm")) | E17: =IF(D17="","",D17*'Exchange Rate'!$E$5) | G17: =IF(F17="","",F17*'Exchange Rate'!$B$5) | H17: =IF(L17="Inactive",0,IF(ISNUMBER(G17)*ISNUMBER(D17),IF(G17>D17,G17-D17,0),0)) -> 0 | I17: =IF(L17="Inactive",0,IF(ISNUMBER(F17)*ISNUMBER(E17),IF(F17>E17,F17-E17,0),0)) -> 0 | J17: =IF(L17="Inactive",0,IF(ISNUMBER(D17)*ISNUMBER(G17),IF(D17>G17,D17-G17,0),0)) -> 0 | K17: =IF(L17="Inactive",0,IF(ISNUMBER(E17)*ISNUMBER(F17),IF(E17>F17,E17-F17,0),0)) -> 0 | L17: Active | M17: =IF(A17="","—",A17&" ("&TEXT(B17,"MM/DD/YYYY")&")") -> —
C18: =IF(B18="","",TEXT(B18,"mmmm")) | E18: =IF(D18="","",D18*'Exchange Rate'!$E$5) | G18: =IF(F18="","",F18*'Exchange Rate'!$B$5) | H18: =IF(L18="Inactive",0,IF(ISNUMBER(G18)*ISNUMBER(D18),IF(G18>D18,G18-D18,0),0)) -> 0 | I18: =IF(L18="Inactive",0,IF(ISNUMBER(F18)*ISNUMBER(E18),IF(F18>E18,F18-E18,0),0)) -> 0 | J18: =IF(L18="Inactive",0,IF(ISNUMBER(D18)*ISNUMBER(G18),IF(D18>G18,D18-G18,0),0)) -> 0 | K18: =IF(L18="Inactive",0,IF(ISNUMBER(E18)*ISNUMBER(F18),IF(E18>F18,E18-F18,0),0)) -> 0 | L18: Active | M18: =IF(A18="","—",A18&" ("&TEXT(B18,"MM/DD/YYYY")&")") -> —
C19: =IF(B19="","",TEXT(B19,"mmmm")) | E19: =IF(D19="","",D19*'Exchange Rate'!$E$5) | G19: =IF(F19="","",F19*'Exchange Rate'!$B$5) | H19: =IF(L19="Inactive",0,IF(ISNUMBER(G19)*ISNUMBER(D19),IF(G19>D19,G19-D19,0),0)) -> 0 | I19: =IF(L19="Inactive",0,IF(ISNUMBER(F19)*ISNUMBER(E19),IF(F19>E19,F19-E19,0),0)) -> 0 | J19: =IF(L19="Inactive",0,IF(ISNUMBER(D19)*ISNUMBER(G19),IF(D19>G19,D19-G19,0),0)) -> 0 | K19: =IF(L19="Inactive",0,IF(ISNUMBER(E19)*ISNUMBER(F19),IF(E19>F19,E19-F19,0),0)) -> 0 | L19: Active | M19: =IF(A19="","—",A19&" ("&TEXT(B19,"MM/DD/YYYY")&")") -> —
... C107: =IF(B107="","",TEXT(B107,"mmmm")) | E107: =IF(D107="","",D107*'Exchange Rate'!$E$5) | G107: =IF(F107="","",F107*'Exchange Rate'!$B$5) | H107: =IF(L107="Inactive",0,IF(ISNUMBER(G107)*ISNUMBER(D107),IF(G107>D107,G107-D107,0),0)) -> 0 | I107: =IF(L107="Inactive",0,IF(ISNUMBER(F107)*ISNUMBER(E107),IF(F107>E107,F107-E107,0),0)) -> 0 | J107: =IF(L107="Inactive",0,IF(ISNUMBER(D107)*ISNUMBER(G107),IF(D107>G107,D107-G107,0),0)) -> 0 | K107: =IF(L107="Inactive",0,IF(ISNUMBER(E107)*ISNUMBER(F107),IF(E107>F107,E107-F107,0),0)) -> 0 | L107: Active | M107: =IF(A107="","—",A107&" ("&TEXT(B107,"MM/DD/YYYY")&")") -> —
A108: TOTAL CATEGORY VALUE | D108: =SUM(D8:D107) -> 0 | E108: =SUM(E8:E107) -> 0 | F108: =SUM(F8:F107) -> 0 | G108: =SUM(G8:G107) -> 0 | H108: =SUM(H8:H107) -> 0 | I108: =SUM(I8:I107) -> 0 | J108: =SUM(J8:J107) -> 0 | K108: =SUM(K8:K107) -> 0 | L108: =SUM(L8:L107) -> 0
A110: 📋 USER GUIDE & OPERATIONAL INSTRUCTIONS
A111: Step 1 — DATA ENTRY
A112: Input rows sequentially. Type directly into Col D (Purchase JPY) and Col F (Selling PHP) ONLY. All other columns auto-calculate. Yellow cells = manual entry. White cells = formulas.
A113: Step 2 — DUPLICATE IDs
A114: If tracking duplicate items, check the QUICK-VIEW bar (Row 5). A ⚠️ alert fires when the same Product ID appears more than once. Use the 'Date of Entry' (Col B) timestamp in the lookup to immediately distinguish which entry is which.
A115: Step 3 — ANALYTICS FILTER
A116: Toggle the Analytics view on the '9. Overall Analytics' sheet using the timeframe filter (D2) to review Weekly, Monthly, or Annual financial health variations.
A117: Step 4 — EXCHANGE RATES
A118: Never manually edit currency columns. To update rates, go to the 'Exchange Rate' sheet and edit ONLY cells B5 (PHP→JPY) or E5 (JPY→PHP). All values across the workbook update instantly.
A119: Step 5 — STOCK STATUS
A120: Use Column L dropdown (Active/Inactive) to toggle items. Inactive rows contribute ZERO to profit, loss, and analytics totals — ideal for recalled, damaged, or discontinued stock.

Sheet 2. Mercari and Online store
A1: KEN JP ANIME FIGURES SHOP
A4: 📦 2. MERCARI AND ONLINE STORE | Rates: 'Exchange Rate'!B5 (PHP→JPY) & E5 (JPY→PHP)
A5: 🔍 FUZZY SEARCH | B5: ⬇ type partial name or ID: | D5: =IF($C$5="","← type above",IFERROR(ROWS(filter($O$8:$O$107,ISNUMBER(SEARCH($C$5,$O$8:$O$107))))&" match(es) found","❌ 0 found")) -> ← type above | E5: View match #: | F5: 1 | G5: =IF($C$5="","— no active search —",IFERROR(INDEX(filter($O$8:$O$107,ISNUMBER(SEARCH($C$5,$O$8:$O$107)),"❌ No Data Found"),VALUE($F$5)),"❌ No Data Found")) -> — no active search — | H5: =IFERROR(IF($G$5="❌ No Data Found","—",IF($G$5="— no active search —","—",INDEX($D$8:$D$107,MATCH($G$5,$O$8:$O$107,0)))),"—") -> — | I5: =IFERROR(IF($G$5="❌ No Data Found","—",IF($G$5="— no active search —","—",INDEX($F$8:$F$107,MATCH($G$5,$O$8:$O$107,0)))),"—") -> — | J5: =IFERROR(IF($G$5="❌ No Data Found","—",IF($G$5="— no active search —","—",INDEX($H$8:$H$107,MATCH($G$5,$O$8:$O$107,0)))),"—") -> — | K5: =IFERROR(IF($G$5="❌ No Data Found","—",IF($G$5="— no active search —","—",INDEX($J$8:$J$107,MATCH($G$5,$O$8:$O$107,0)))),"—") -> — | L5: =IFERROR(IF($G$5="❌ No Data Found","—",IF($G$5="— no active search —","—",INDEX($L$8:$L$107,MATCH($G$5,$O$8:$O$107,0)))),"—") -> —
A7: Product ID | B7: Date of Entry | C7: Transaction Month | D7: Purchase Price (JPY) | E7: Purchase Price (PHP) | F7: Selling Price (PHP) | G7: Selling Price (JPY) | H7: Net Profit (JPY) | I7: Net Profit (PHP) | J7: Net Loss (JPY) | K7: Net Loss (PHP) | L7: Stock Status | M7: Customer Name | N7: Purchase Link | O7: SEARCH_KEY (hidden)
C8: =IF(B8="","",TEXT(B8,"mmmm")) | E8: =IF(D8="","",D8*'Exchange Rate'!$E$5) | G8: =IF(F8="","",F8*'Exchange Rate'!$B$5) | H8: =IF(L8="Inactive",0,IF(ISNUMBER(G8)*ISNUMBER(D8),IF(G8>D8,G8-D8,0),0)) -> 0 | I8: =IF(L8="Inactive",0,IF(ISNUMBER(F8)*ISNUMBER(E8),IF(F8>E8,F8-E8,0),0)) -> 0 | J8: =IF(L8="Inactive",0,IF(ISNUMBER(D8)*ISNUMBER(G8),IF(D8>G8,D8-G8,0),0)) -> 0 | K8: =IF(L8="Inactive",0,IF(ISNUMBER(E8)*ISNUMBER(F8),IF(E8>F8,E8-F8,0),0)) -> 0 | L8: Active | O8: =IF(A8="","—",A8&" ("&TEXT(B8,"MM/DD/YYYY")&")") -> —
C9: =IF(B9="","",TEXT(B9,"mmmm")) | E9: =IF(D9="","",D9*'Exchange Rate'!$E$5) | G9: =IF(F9="","",F9*'Exchange Rate'!$B$5) | H9: =IF(L9="Inactive",0,IF(ISNUMBER(G9)*ISNUMBER(D9),IF(G9>D9,G9-D9,0),0)) -> 0 | I9: =IF(L9="Inactive",0,IF(ISNUMBER(F9)*ISNUMBER(E9),IF(F9>E9,F9-E9,0),0)) -> 0 | J9: =IF(L9="Inactive",0,IF(ISNUMBER(D9)*ISNUMBER(G9),IF(D9>G9,D9-G9,0),0)) -> 0 | K9: =IF(L9="Inactive",0,IF(ISNUMBER(E9)*ISNUMBER(F9),IF(E9>F9,E9-F9,0),0)) -> 0 | L9: Active | O9: =IF(A9="","—",A9&" ("&TEXT(B9,"MM/DD/YYYY")&")") -> —
C10: =IF(B10="","",TEXT(B10,"mmmm")) | E10: =IF(D10="","",D10*'Exchange Rate'!$E$5) | G10: =IF(F10="","",F10*'Exchange Rate'!$B$5) | H10: =IF(L10="Inactive",0,IF(ISNUMBER(G10)*ISNUMBER(D10),IF(G10>D10,G10-D10,0),0)) -> 0 | I10: =IF(L10="Inactive",0,IF(ISNUMBER(F10)*ISNUMBER(E10),IF(F10>E10,F10-E10,0),0)) -> 0 | J10: =IF(L10="Inactive",0,IF(ISNUMBER(D10)*ISNUMBER(G10),IF(D10>G10,D10-G10,0),0)) -> 0 | K10: =IF(L10="Inactive",0,IF(ISNUMBER(E10)*ISNUMBER(F10),IF(E10>F10,E10-F10,0),0)) -> 0 | L10: Active | O10: =IF(A10="","—",A10&" ("&TEXT(B10,"MM/DD/YYYY")&")") -> —
C11: =IF(B11="","",TEXT(B11,"mmmm")) | E11: =IF(D11="","",D11*'Exchange Rate'!$E$5) | G11: =IF(F11="","",F11*'Exchange Rate'!$B$5) | H11: =IF(L11="Inactive",0,IF(ISNUMBER(G11)*ISNUMBER(D11),IF(G11>D11,G11-D11,0),0)) -> 0 | I11: =IF(L11="Inactive",0,IF(ISNUMBER(F11)*ISNUMBER(E11),IF(F11>E11,F11-E11,0),0)) -> 0 | J11: =IF(L11="Inactive",0,IF(ISNUMBER(D11)*ISNUMBER(G11),IF(D11>G11,D11-G11,0),0)) -> 0 | K11: =IF(L11="Inactive",0,IF(ISNUMBER(E11)*ISNUMBER(F11),IF(E11>F11,E11-F11,0),0)) -> 0 | L11: Active | O11: =IF(A11="","—",A11&" ("&TEXT(B11,"MM/DD/YYYY")&")") -> —
C12: =IF(B12="","",TEXT(B12,"mmmm")) | E12: =IF(D12="","",D12*'Exchange Rate'!$E$5) | G12: =IF(F12="","",F12*'Exchange Rate'!$B$5) | H12: =IF(L12="Inactive",0,IF(ISNUMBER(G12)*ISNUMBER(D12),IF(G12>D12,G12-D12,0),0)) -> 0 | I12: =IF(L12="Inactive",0,IF(ISNUMBER(F12)*ISNUMBER(E12),IF(F12>E12,F12-E12,0),0)) -> 0 | J12: =IF(L12="Inactive",0,IF(ISNUMBER(D12)*ISNUMBER(G12),IF(D12>G12,D12-G12,0),0)) -> 0 | K12: =IF(L12="Inactive",0,IF(ISNUMBER(E12)*ISNUMBER(F12),IF(E12>F12,E12-F12,0),0)) -> 0 | L12: Active | O12: =IF(A12="","—",A12&" ("&TEXT(B12,"MM/DD/YYYY")&")") -> —
C13: =IF(B13="","",TEXT(B13,"mmmm")) | E13: =IF(D13="","",D13*'Exchange Rate'!$E$5) | G13: =IF(F13="","",F13*'Exchange Rate'!$B$5) | H13: =IF(L13="Inactive",0,IF(ISNUMBER(G13)*ISNUMBER(D13),IF(G13>D13,G13-D13,0),0)) -> 0 | I13: =IF(L13="Inactive",0,IF(ISNUMBER(F13)*ISNUMBER(E13),IF(F13>E13,F13-E13,0),0)) -> 0 | J13: =IF(L13="Inactive",0,IF(ISNUMBER(D13)*ISNUMBER(G13),IF(D13>G13,D13-G13,0),0)) -> 0 | K13: =IF(L13="Inactive",0,IF(ISNUMBER(E13)*ISNUMBER(F13),IF(E13>F13,E13-F13,0),0)) -> 0 | L13: Active | O13: =IF(A13="","—",A13&" ("&TEXT(B13,"MM/DD/YYYY")&")") -> —
C14: =IF(B14="","",TEXT(B14,"mmmm")) | E14: =IF(D14="","",D14*'Exchange Rate'!$E$5) | G14: =IF(F14="","",F14*'Exchange Rate'!$B$5) | H14: =IF(L14="Inactive",0,IF(ISNUMBER(G14)*ISNUMBER(D14),IF(G14>D14,G14-D14,0),0)) -> 0 | I14: =IF(L14="Inactive",0,IF(ISNUMBER(F14)*ISNUMBER(E14),IF(F14>E14,F14-E14,0),0)) -> 0 | J14: =IF(L14="Inactive",0,IF(ISNUMBER(D14)*ISNUMBER(G14),IF(D14>G14,D14-G14,0),0)) -> 0 | K14: =IF(L14="Inactive",0,IF(ISNUMBER(E14)*ISNUMBER(F14),IF(E14>F14,E14-F14,0),0)) -> 0 | L14: Active | O14: =IF(A14="","—",A14&" ("&TEXT(B14,"MM/DD/YYYY")&")") -> —
C15: =IF(B15="","",TEXT(B15,"mmmm")) | E15: =IF(D15="","",D15*'Exchange Rate'!$E$5) | G15: =IF(F15="","",F15*'Exchange Rate'!$B$5) | H15: =IF(L15="Inactive",0,IF(ISNUMBER(G15)*ISNUMBER(D15),IF(G15>D15,G15-D15,0),0)) -> 0 | I15: =IF(L15="Inactive",0,IF(ISNUMBER(F15)*ISNUMBER(E15),IF(F15>E15,F15-E15,0),0)) -> 0 | J15: =IF(L15="Inactive",0,IF(ISNUMBER(D15)*ISNUMBER(G15),IF(D15>G15,D15-G15,0),0)) -> 0 | K15: =IF(L15="Inactive",0,IF(ISNUMBER(E15)*ISNUMBER(F15),IF(E15>F15,E15-F15,0),0)) -> 0 | L15: Active | O15: =IF(A15="","—",A15&" ("&TEXT(B15,"MM/DD/YYYY")&")") -> —
C16: =IF(B16="","",TEXT(B16,"mmmm")) | E16: =IF(D16="","",D16*'Exchange Rate'!$E$5) | G16: =IF(F16="","",F16*'Exchange Rate'!$B$5) | H16: =IF(L16="Inactive",0,IF(ISNUMBER(G16)*ISNUMBER(D16),IF(G16>D16,G16-D16,0),0)) -> 0 | I16: =IF(L16="Inactive",0,IF(ISNUMBER(F16)*ISNUMBER(E16),IF(F16>E16,F16-E16,0),0)) -> 0 | J16: =IF(L16="Inactive",0,IF(ISNUMBER(D16)*ISNUMBER(G16),IF(D16>G16,D16-G16,0),0)) -> 0 | K16: =IF(L16="Inactive",0,IF(ISNUMBER(E16)*ISNUMBER(F16),IF(E16>F16,E16-F16,0),0)) -> 0 | L16: Active | O16: =IF(A16="","—",A16&" ("&TEXT(B16,"MM/DD/YYYY")&")") -> —
C17: =IF(B17="","",TEXT(B17,"mmmm")) | E17: =IF(D17="","",D17*'Exchange Rate'!$E$5) | G17: =IF(F17="","",F17*'Exchange Rate'!$B$5) | H17: =IF(L17="Inactive",0,IF(ISNUMBER(G17)*ISNUMBER(D17),IF(G17>D17,G17-D17,0),0)) -> 0 | I17: =IF(L17="Inactive",0,IF(ISNUMBER(F17)*ISNUMBER(E17),IF(F17>E17,F17-E17,0),0)) -> 0 | J17: =IF(L17="Inactive",0,IF(ISNUMBER(D17)*ISNUMBER(G17),IF(D17>G17,D17-G17,0),0)) -> 0 | K17: =IF(L17="Inactive",0,IF(ISNUMBER(E17)*ISNUMBER(F17),IF(E17>F17,E17-F17,0),0)) -> 0 | L17: Active | O17: =IF(A17="","—",A17&" ("&TEXT(B17,"MM/DD/YYYY")&")") -> —
C18: =IF(B18="","",TEXT(B18,"mmmm")) | E18: =IF(D18="","",D18*'Exchange Rate'!$E$5) | G18: =IF(F18="","",F18*'Exchange Rate'!$B$5) | H18: =IF(L18="Inactive",0,IF(ISNUMBER(G18)*ISNUMBER(D18),IF(G18>D18,G18-D18,0),0)) -> 0 | I18: =IF(L18="Inactive",0,IF(ISNUMBER(F18)*ISNUMBER(E18),IF(F18>E18,F18-E18,0),0)) -> 0 | J18: =IF(L18="Inactive",0,IF(ISNUMBER(D18)*ISNUMBER(G18),IF(D18>G18,D18-G18,0),0)) -> 0 | K18: =IF(L18="Inactive",0,IF(ISNUMBER(E18)*ISNUMBER(F18),IF(E18>F18,E18-F18,0),0)) -> 0 | L18: Active | O18: =IF(A18="","—",A18&" ("&TEXT(B18,"MM/DD/YYYY")&")") -> —
C19: =IF(B19="","",TEXT(B19,"mmmm")) | E19: =IF(D19="","",D19*'Exchange Rate'!$E$5) | G19: =IF(F19="","",F19*'Exchange Rate'!$B$5) | H19: =IF(L19="Inactive",0,IF(ISNUMBER(G19)*ISNUMBER(D19),IF(G19>D19,G19-D19,0),0)) -> 0 | I19: =IF(L19="Inactive",0,IF(ISNUMBER(F19)*ISNUMBER(E19),IF(F19>E19,F19-E19,0),0)) -> 0 | J19: =IF(L19="Inactive",0,IF(ISNUMBER(D19)*ISNUMBER(G19),IF(D19>G19,D19-G19,0),0)) -> 0 | K19: =IF(L19="Inactive",0,IF(ISNUMBER(E19)*ISNUMBER(F19),IF(E19>F19,E19-F19,0),0)) -> 0 | L19: Active | O19: =IF(A19="","—",A19&" ("&TEXT(B19,"MM/DD/YYYY")&")") -> —
... C107: =IF(B107="","",TEXT(B107,"mmmm")) | E107: =IF(D107="","",D107*'Exchange Rate'!$E$5) | G107: =IF(F107="","",F107*'Exchange Rate'!$B$5) | H107: =IF(L107="Inactive",0,IF(ISNUMBER(G107)*ISNUMBER(D107),IF(G107>D107,G107-D107,0),0)) -> 0 | I107: =IF(L107="Inactive",0,IF(ISNUMBER(F107)*ISNUMBER(E107),IF(F107>E107,F107-E107,0),0)) -> 0 | J107: =IF(L107="Inactive",0,IF(ISNUMBER(D107)*ISNUMBER(G107),IF(D107>G107,D107-G107,0),0)) -> 0 | K107: =IF(L107="Inactive",0,IF(ISNUMBER(E107)*ISNUMBER(F107),IF(E107>F107,E107-F107,0),0)) -> 0 | L107: Active | O107: =IF(A107="","—",A107&" ("&TEXT(B107,"MM/DD/YYYY")&")") -> —
A108: TOTAL CATEGORY VALUE | D108: =SUM(D8:D107) -> 0 | E108: =SUM(E8:E107) -> 0 | F108: =SUM(F8:F107) -> 0 | G108: =SUM(G8:G107) -> 0 | H108: =SUM(H8:H107) -> 0 | I108: =SUM(I8:I107) -> 0 | J108: =SUM(J8:J107) -> 0 | K108: =SUM(K8:K107) -> 0 | ... N108: =SUM(N8:N107) -> 0
A110: 📋 USER GUIDE & OPERATIONAL INSTRUCTIONS
A111: Step 1 — DATA ENTRY
A112: Input rows sequentially. Type directly into Col D (Purchase JPY) and Col F (Selling PHP) ONLY. All other columns auto-calculate. Yellow cells = manual entry. White cells = formulas.
A113: Step 2 — DUPLICATE IDs
A114: If tracking duplicate items, check the QUICK-VIEW bar (Row 5). A ⚠️ alert fires when the same Product ID appears more than once. Use the 'Date of Entry' (Col B) timestamp in the lookup to immediately distinguish which entry is which.
A115: Step 3 — ANALYTICS FILTER
A116: Toggle the Analytics view on the '9. Overall Analytics' sheet using the timeframe filter (D2) to review Weekly, Monthly, or Annual financial health variations.
A117: Step 4 — EXCHANGE RATES
A118: Never manually edit currency columns. To update rates, go to the 'Exchange Rate' sheet and edit ONLY cells B5 (PHP→JPY) or E5 (JPY→PHP). All values across the workbook update instantly.
A119: Step 5 — STOCK STATUS
A120: Use Column L dropdown (Active/Inactive) to toggle items. Inactive rows contribute ZERO to profit, loss, and analytics totals — ideal for recalled, damaged, or discontinued stock.

Sheet 3. Onhand orders JPY
A1: KEN JP ANIME FIGURES SHOP
A4: 📦 3. ONHAND ORDERS JPY | Rates: 'Exchange Rate'!B5 (PHP→JPY) & E5 (JPY→PHP)
A5: 🔍 FUZZY SEARCH | B5: ⬇ type partial name or ID: | D5: =IF($C$5="","← type above",IFERROR(ROWS(filter($M$8:$M$107,ISNUMBER(SEARCH($C$5,$M$8:$M$107))))&" match(es) found","❌ 0 found")) -> ← type above | E5: View match #: | F5: 1 | G5: =IF($C$5="","— no active search —",IFERROR(INDEX(filter($M$8:$M$107,ISNUMBER(SEARCH($C$5,$M$8:$M$107)),"❌ No Data Found"),VALUE($F$5)),"❌ No Data Found")) -> — no active search — | H5: =IFERROR(IF($G$5="❌ No Data Found","—",IF($G$5="— no active search —","—",INDEX($D$8:$D$107,MATCH($G$5,$M$8:$M$107,0)))),"—") -> — | I5: =IFERROR(IF($G$5="❌ No Data Found","—",IF($G$5="— no active search —","—",INDEX($F$8:$F$107,MATCH($G$5,$M$8:$M$107,0)))),"—") -> — | J5: =IFERROR(IF($G$5="❌ No Data Found","—",IF($G$5="— no active search —","—",INDEX($H$8:$H$107,MATCH($G$5,$M$8:$M$107,0)))),"—") -> — | K5: =IFERROR(IF($G$5="❌ No Data Found","—",IF($G$5="— no active search —","—",INDEX($J$8:$J$107,MATCH($G$5,$M$8:$M$107,0)))),"—") -> — | L5: =IFERROR(IF($G$5="❌ No Data Found","—",IF($G$5="— no active search —","—",INDEX($L$8:$L$107,MATCH($G$5,$M$8:$M$107,0)))),"—") -> —
A7: Product ID | B7: Date of Entry | C7: Transaction Month | D7: Purchase Price (JPY) | E7: Purchase Price (PHP) | F7: Selling Price (PHP) | G7: Selling Price (JPY) | H7: Net Profit (JPY) | I7: Net Profit (PHP) | J7: Net Loss (JPY) | K7: Net Loss (PHP) | L7: Stock Status | M7: SEARCH_KEY (hidden)
C8: =IF(B8="","",TEXT(B8,"mmmm")) | E8: =IF(D8="","",D8*'Exchange Rate'!$E$5) | G8: =IF(F8="","",F8*'Exchange Rate'!$B$5) | H8: =IF(L8="Inactive",0,IF(ISNUMBER(G8)*ISNUMBER(D8),IF(G8>D8,G8-D8,0),0)) -> 0 | I8: =IF(L8="Inactive",0,IF(ISNUMBER(F8)*ISNUMBER(E8),IF(F8>E8,F8-E8,0),0)) -> 0 | J8: =IF(L8="Inactive",0,IF(ISNUMBER(D8)*ISNUMBER(G8),IF(D8>G8,D8-G8,0),0)) -> 0 | K8: =IF(L8="Inactive",0,IF(ISNUMBER(E8)*ISNUMBER(F8),IF(E8>F8,E8-F8,0),0)) -> 0 | L8: Active | M8: =IF(A8="","—",A8&" ("&TEXT(B8,"MM/DD/YYYY")&")") -> —
C9: =IF(B9="","",TEXT(B9,"mmmm")) | E9: =IF(D9="","",D9*'Exchange Rate'!$E$5) | G9: =IF(F9="","",F9*'Exchange Rate'!$B$5) | H9: =IF(L9="Inactive",0,IF(ISNUMBER(G9)*ISNUMBER(D9),IF(G9>D9,G9-D9,0),0)) -> 0 | I9: =IF(L9="Inactive",0,IF(ISNUMBER(F9)*ISNUMBER(E9),IF(F9>E9,F9-E9,0),0)) -> 0 | J9: =IF(L9="Inactive",0,IF(ISNUMBER(D9)*ISNUMBER(G9),IF(D9>G9,D9-G9,0),0)) -> 0 | K9: =IF(L9="Inactive",0,IF(ISNUMBER(E9)*ISNUMBER(F9),IF(E9>F9,E9-F9,0),0)) -> 0 | L9: Active | M9: =IF(A9="","—",A9&" ("&TEXT(B9,"MM/DD/YYYY")&")") -> —
C10: =IF(B10="","",TEXT(B10,"mmmm")) | E10: =IF(D10="","",D10*'Exchange Rate'!$E$5) | G10: =IF(F10="","",F10*'Exchange Rate'!$B$5) | H10: =IF(L10="Inactive",0,IF(ISNUMBER(G10)*ISNUMBER(D10),IF(G10>D10,G10-D10,0),0)) -> 0 | I10: =IF(L10="Inactive",0,IF(ISNUMBER(F10)*ISNUMBER(E10),IF(F10>E10,F10-E10,0),0)) -> 0 | J10: =IF(L10="Inactive",0,IF(ISNUMBER(D10)*ISNUMBER(G10),IF(D10>G10,D10-G10,0),0)) -> 0 | K10: =IF(L10="Inactive",0,IF(ISNUMBER(E10)*ISNUMBER(F10),IF(E10>F10,E10-F10,0),0)) -> 0 | L10: Active | M10: =IF(A10="","—",A10&" ("&TEXT(B10,"MM/DD/YYYY")&")") -> —
C11: =IF(B11="","",TEXT(B11,"mmmm")) | E11: =IF(D11="","",D11*'Exchange Rate'!$E$5) | G11: =IF(F11="","",F11*'Exchange Rate'!$B$5) | H11: =IF(L11="Inactive",0,IF(ISNUMBER(G11)*ISNUMBER(D11),IF(G11>D11,G11-D11,0),0)) -> 0 | I11: =IF(L11="Inactive",0,IF(ISNUMBER(F11)*ISNUMBER(E11),IF(F11>E11,F11-E11,0),0)) -> 0 | J11: =IF(L11="Inactive",0,IF(ISNUMBER(D11)*ISNUMBER(G11),IF(D11>G11,D11-G11,0),0)) -> 0 | K11: =IF(L11="Inactive",0,IF(ISNUMBER(E11)*ISNUMBER(F11),IF(E11>F11,E11-F11,0),0)) -> 0 | L11: Active | M11: =IF(A11="","—",A11&" ("&TEXT(B11,"MM/DD/YYYY")&")") -> —
C12: =IF(B12="","",TEXT(B12,"mmmm")) | E12: =IF(D12="","",D12*'Exchange Rate'!$E$5) | G12: =IF(F12="","",F12*'Exchange Rate'!$B$5) | H12: =IF(L12="Inactive",0,IF(ISNUMBER(G12)*ISNUMBER(D12),IF(G12>D12,G12-D12,0),0)) -> 0 | I12: =IF(L12="Inactive",0,IF(ISNUMBER(F12)*ISNUMBER(E12),IF(F12>E12,F12-E12,0),0)) -> 0 | J12: =IF(L12="Inactive",0,IF(ISNUMBER(D12)*ISNUMBER(G12),IF(D12>G12,D12-G12,0),0)) -> 0 | K12: =IF(L12="Inactive",0,IF(ISNUMBER(E12)*ISNUMBER(F12),IF(E12>F12,E12-F12,0),0)) -> 0 | L12: Active | M12: =IF(A12="","—",A12&" ("&TEXT(B12,"MM/DD/YYYY")&")") -> —
C13: =IF(B13="","",TEXT(B13,"mmmm")) | E13: =IF(D13="","",D13*'Exchange Rate'!$E$5) | G13: =IF(F13="","",F13*'Exchange Rate'!$B$5) | H13: =IF(L13="Inactive",0,IF(ISNUMBER(G13)*ISNUMBER(D13),IF(G13>D13,G13-D13,0),0)) -> 0 | I13: =IF(L13="Inactive",0,IF(ISNUMBER(F13)*ISNUMBER(E13),IF(F13>E13,F13-E13,0),0)) -> 0 | J13: =IF(L13="Inactive",0,IF(ISNUMBER(D13)*ISNUMBER(G13),IF(D13>G13,D13-G13,0),0)) -> 0 | K13: =IF(L13="Inactive",0,IF(ISNUMBER(E13)*ISNUMBER(F13),IF(E13>F13,E13-F13,0),0)) -> 0 | L13: Active | M13: =IF(A13="","—",A13&" ("&TEXT(B13,"MM/DD/YYYY")&")") -> —
C14: =IF(B14="","",TEXT(B14,"mmmm")) | E14: =IF(D14="","",D14*'Exchange Rate'!$E$5) | G14: =IF(F14="","",F14*'Exchange Rate'!$B$5) | H14: =IF(L14="Inactive",0,IF(ISNUMBER(G14)*ISNUMBER(D14),IF(G14>D14,G14-D14,0),0)) -> 0 | I14: =IF(L14="Inactive",0,IF(ISNUMBER(F14)*ISNUMBER(E14),IF(F14>E14,F14-E14,0),0)) -> 0 | J14: =IF(L14="Inactive",0,IF(ISNUMBER(D14)*ISNUMBER(G14),IF(D14>G14,D14-G14,0),0)) -> 0 | K14: =IF(L14="Inactive",0,IF(ISNUMBER(E14)*ISNUMBER(F14),IF(E14>F14,E14-F14,0),0)) -> 0 | L14: Active | M14: =IF(A14="","—",A14&" ("&TEXT(B14,"MM/DD/YYYY")&")") -> —
C15: =IF(B15="","",TEXT(B15,"mmmm")) | E15: =IF(D15="","",D15*'Exchange Rate'!$E$5) | G15: =IF(F15="","",F15*'Exchange Rate'!$B$5) | H15: =IF(L15="Inactive",0,IF(ISNUMBER(G15)*ISNUMBER(D15),IF(G15>D15,G15-D15,0),0)) -> 0 | I15: =IF(L15="Inactive",0,IF(ISNUMBER(F15)*ISNUMBER(E15),IF(F15>E15,F15-E15,0),0)) -> 0 | J15: =IF(L15="Inactive",0,IF(ISNUMBER(D15)*ISNUMBER(G15),IF(D15>G15,D15-G15,0),0)) -> 0 | K15: =IF(L15="Inactive",0,IF(ISNUMBER(E15)*ISNUMBER(F15),IF(E15>F15,E15-F15,0),0)) -> 0 | L15: Active | M15: =IF(A15="","—",A15&" ("&TEXT(B15,"MM/DD/YYYY")&")") -> —
C16: =IF(B16="","",TEXT(B16,"mmmm")) | E16: =IF(D16="","",D16*'Exchange Rate'!$E$5) | G16: =IF(F16="","",F16*'Exchange Rate'!$B$5) | H16: =IF(L16="Inactive",0,IF(ISNUMBER(G16)*ISNUMBER(D16),IF(G16>D16,G16-D16,0),0)) -> 0 | I16: =IF(L16="Inactive",0,IF(ISNUMBER(F16)*ISNUMBER(E16),IF(F16>E16,F16-E16,0),0)) -> 0 | J16: =IF(L16="Inactive",0,IF(ISNUMBER(D16)*ISNUMBER(G16),IF(D16>G16,D16-G16,0),0)) -> 0 | K16: =IF(L16="Inactive",0,IF(ISNUMBER(E16)*ISNUMBER(F16),IF(E16>F16,E16-F16,0),0)) -> 0 | L16: Active | M16: =IF(A16="","—",A16&" ("&TEXT(B16,"MM/DD/YYYY")&")") -> —
C17: =IF(B17="","",TEXT(B17,"mmmm")) | E17: =IF(D17="","",D17*'Exchange Rate'!$E$5) | G17: =IF(F17="","",F17*'Exchange Rate'!$B$5) | H17: =IF(L17="Inactive",0,IF(ISNUMBER(G17)*ISNUMBER(D17),IF(G17>D17,G17-D17,0),0)) -> 0 | I17: =IF(L17="Inactive",0,IF(ISNUMBER(F17)*ISNUMBER(E17),IF(F17>E17,F17-E17,0),0)) -> 0 | J17: =IF(L17="Inactive",0,IF(ISNUMBER(D17)*ISNUMBER(G17),IF(D17>G17,D17-G17,0),0)) -> 0 | K17: =IF(L17="Inactive",0,IF(ISNUMBER(E17)*ISNUMBER(F17),IF(E17>F17,E17-F17,0),0)) -> 0 | L17: Active | M17: =IF(A17="","—",A17&" ("&TEXT(B17,"MM/DD/YYYY")&")") -> —
C18: =IF(B18="","",TEXT(B18,"mmmm")) | E18: =IF(D18="","",D18*'Exchange Rate'!$E$5) | G18: =IF(F18="","",F18*'Exchange Rate'!$B$5) | H18: =IF(L18="Inactive",0,IF(ISNUMBER(G18)*ISNUMBER(D18),IF(G18>D18,G18-D18,0),0)) -> 0 | I18: =IF(L18="Inactive",0,IF(ISNUMBER(F18)*ISNUMBER(E18),IF(F18>E18,F18-E18,0),0)) -> 0 | J18: =IF(L18="Inactive",0,IF(ISNUMBER(D18)*ISNUMBER(G18),IF(D18>G18,D18-G18,0),0)) -> 0 | K18: =IF(L18="Inactive",0,IF(ISNUMBER(E18)*ISNUMBER(F18),IF(E18>F18,E18-F18,0),0)) -> 0 | L18: Active | M18: =IF(A18="","—",A18&" ("&TEXT(B18,"MM/DD/YYYY")&")") -> —
C19: =IF(B19="","",TEXT(B19,"mmmm")) | E19: =IF(D19="","",D19*'Exchange Rate'!$E$5) | G19: =IF(F19="","",F19*'Exchange Rate'!$B$5) | H19: =IF(L19="Inactive",0,IF(ISNUMBER(G19)*ISNUMBER(D19),IF(G19>D19,G19-D19,0),0)) -> 0 | I19: =IF(L19="Inactive",0,IF(ISNUMBER(F19)*ISNUMBER(E19),IF(F19>E19,F19-E19,0),0)) -> 0 | J19: =IF(L19="Inactive",0,IF(ISNUMBER(D19)*ISNUMBER(G19),IF(D19>G19,D19-G19,0),0)) -> 0 | K19: =IF(L19="Inactive",0,IF(ISNUMBER(E19)*ISNUMBER(F19),IF(E19>F19,E19-F19,0),0)) -> 0 | L19: Active | M19: =IF(A19="","—",A19&" ("&TEXT(B19,"MM/DD/YYYY")&")") -> —
... C107: =IF(B107="","",TEXT(B107,"mmmm")) | E107: =IF(D107="","",D107*'Exchange Rate'!$E$5) | G107: =IF(F107="","",F107*'Exchange Rate'!$B$5) | H107: =IF(L107="Inactive",0,IF(ISNUMBER(G107)*ISNUMBER(D107),IF(G107>D107,G107-D107,0),0)) -> 0 | I107: =IF(L107="Inactive",0,IF(ISNUMBER(F107)*ISNUMBER(E107),IF(F107>E107,F107-E107,0),0)) -> 0 | J107: =IF(L107="Inactive",0,IF(ISNUMBER(D107)*ISNUMBER(G107),IF(D107>G107,D107-G107,0),0)) -> 0 | K107: =IF(L107="Inactive",0,IF(ISNUMBER(E107)*ISNUMBER(F107),IF(E107>F107,E107-F107,0),0)) -> 0 | L107: Active | M107: =IF(A107="","—",A107&" ("&TEXT(B107,"MM/DD/YYYY")&")") -> —
A108: TOTAL CATEGORY VALUE | D108: =SUM(D8:D107) -> 0 | E108: =SUM(E8:E107) -> 0 | F108: =SUM(F8:F107) -> 0 | G108: =SUM(G8:G107) -> 0 | H108: =SUM(H8:H107) -> 0 | I108: =SUM(I8:I107) -> 0 | J108: =SUM(J8:J107) -> 0 | K108: =SUM(K8:K107) -> 0 | L108: =SUM(L8:L107) -> 0
A110: 📋 USER GUIDE & OPERATIONAL INSTRUCTIONS
A111: Step 1 — DATA ENTRY
A112: Input rows sequentially. Type directly into Col D (Purchase JPY) and Col F (Selling PHP) ONLY. All other columns auto-calculate. Yellow cells = manual entry. White cells = formulas.
A113: Step 2 — DUPLICATE IDs
A114: If tracking duplicate items, check the QUICK-VIEW bar (Row 5). A ⚠️ alert fires when the same Product ID appears more than once. Use the 'Date of Entry' (Col B) timestamp in the lookup to immediately distinguish which entry is which.
A115: Step 3 — ANALYTICS FILTER
A116: Toggle the Analytics view on the '9. Overall Analytics' sheet using the timeframe filter (D2) to review Weekly, Monthly, or Annual financial health variations.
A117: Step 4 — EXCHANGE RATES
A118: Never manually edit currency columns. To update rates, go to the 'Exchange Rate' sheet and edit ONLY cells B5 (PHP→JPY) or E5 (JPY→PHP). All values across the workbook update instantly.
A119: Step 5 — STOCK STATUS
A120: Use Column L dropdown (Active/Inactive) to toggle items. Inactive rows contribute ZERO to profit, loss, and analytics totals — ideal for recalled, damaged, or discontinued stock.

Sheet 4. Live Selling Orders
A1: KEN JP ANIME FIGURES SHOP
A4: 📦 4. LIVE SELLING ORDERS | Rates: 'Exchange Rate'!B5 (PHP→JPY) & E5 (JPY→PHP)
A5: 🔍 FUZZY SEARCH | B5: ⬇ type partial name or ID: | D5: =IF($C$5="","← type above",IFERROR(ROWS(filter($M$8:$M$107,ISNUMBER(SEARCH($C$5,$M$8:$M$107))))&" match(es) found","❌ 0 found")) -> ← type above | E5: View match #: | F5: 1 | G5: =IF($C$5="","— no active search —",IFERROR(INDEX(filter($M$8:$M$107,ISNUMBER(SEARCH($C$5,$M$8:$M$107)),"❌ No Data Found"),VALUE($F$5)),"❌ No Data Found")) -> — no active search — | H5: =IFERROR(IF($G$5="❌ No Data Found","—",IF($G$5="— no active search —","—",INDEX($D$8:$D$107,MATCH($G$5,$M$8:$M$107,0)))),"—") -> — | I5: =IFERROR(IF($G$5="❌ No Data Found","—",IF($G$5="— no active search —","—",INDEX($F$8:$F$107,MATCH($G$5,$M$8:$M$107,0)))),"—") -> — | J5: =IFERROR(IF($G$5="❌ No Data Found","—",IF($G$5="— no active search —","—",INDEX($H$8:$H$107,MATCH($G$5,$M$8:$M$107,0)))),"—") -> — | K5: =IFERROR(IF($G$5="❌ No Data Found","—",IF($G$5="— no active search —","—",INDEX($J$8:$J$107,MATCH($G$5,$M$8:$M$107,0)))),"—") -> — | L5: =IFERROR(IF($G$5="❌ No Data Found","—",IF($G$5="— no active search —","—",INDEX($L$8:$L$107,MATCH($G$5,$M$8:$M$107,0)))),"—") -> —
A7: Product ID | B7: Date of Entry | C7: Transaction Month | D7: Purchase Price (JPY) | E7: Purchase Price (PHP) | F7: Selling Price (PHP) | G7: Selling Price (JPY) | H7: Net Profit (JPY) | I7: Net Profit (PHP) | J7: Net Loss (JPY) | K7: Net Loss (PHP) | L7: Stock Status | M7: SEARCH_KEY (hidden)
C8: =IF(B8="","",TEXT(B8,"mmmm")) | E8: =IF(D8="","",D8*'Exchange Rate'!$E$5) | G8: =IF(F8="","",F8*'Exchange Rate'!$B$5) | H8: =IF(L8="Inactive",0,IF(ISNUMBER(G8)*ISNUMBER(D8),IF(G8>D8,G8-D8,0),0)) -> 0 | I8: =IF(L8="Inactive",0,IF(ISNUMBER(F8)*ISNUMBER(E8),IF(F8>E8,F8-E8,0),0)) -> 0 | J8: =IF(L8="Inactive",0,IF(ISNUMBER(D8)*ISNUMBER(G8),IF(D8>G8,D8-G8,0),0)) -> 0 | K8: =IF(L8="Inactive",0,IF(ISNUMBER(E8)*ISNUMBER(F8),IF(E8>F8,E8-F8,0),0)) -> 0 | L8: Active | M8: =IF(A8="","—",A8&" ("&TEXT(B8,"MM/DD/YYYY")&")") -> —
C9: =IF(B9="","",TEXT(B9,"mmmm")) | E9: =IF(D9="","",D9*'Exchange Rate'!$E$5) | G9: =IF(F9="","",F9*'Exchange Rate'!$B$5) | H9: =IF(L9="Inactive",0,IF(ISNUMBER(G9)*ISNUMBER(D9),IF(G9>D9,G9-D9,0),0)) -> 0 | I9: =IF(L9="Inactive",0,IF(ISNUMBER(F9)*ISNUMBER(E9),IF(F9>E9,F9-E9,0),0)) -> 0 | J9: =IF(L9="Inactive",0,IF(ISNUMBER(D9)*ISNUMBER(G9),IF(D9>G9,D9-G9,0),0)) -> 0 | K9: =IF(L9="Inactive",0,IF(ISNUMBER(E9)*ISNUMBER(F9),IF(E9>F9,E9-F9,0),0)) -> 0 | L9: Active | M9: =IF(A9="","—",A9&" ("&TEXT(B9,"MM/DD/YYYY")&")") -> —
C10: =IF(B10="","",TEXT(B10,"mmmm")) | E10: =IF(D10="","",D10*'Exchange Rate'!$E$5) | G10: =IF(F10="","",F10*'Exchange Rate'!$B$5) | H10: =IF(L10="Inactive",0,IF(ISNUMBER(G10)*ISNUMBER(D10),IF(G10>D10,G10-D10,0),0)) -> 0 | I10: =IF(L10="Inactive",0,IF(ISNUMBER(F10)*ISNUMBER(E10),IF(F10>E10,F10-E10,0),0)) -> 0 | J10: =IF(L10="Inactive",0,IF(ISNUMBER(D10)*ISNUMBER(G10),IF(D10>G10,D10-G10,0),0)) -> 0 | K10: =IF(L10="Inactive",0,IF(ISNUMBER(E10)*ISNUMBER(F10),IF(E10>F10,E10-F10,0),0)) -> 0 | L10: Active | M10: =IF(A10="","—",A10&" ("&TEXT(B10,"MM/DD/YYYY")&")") -> —
C11: =IF(B11="","",TEXT(B11,"mmmm")) | E11: =IF(D11="","",D11*'Exchange Rate'!$E$5) | G11: =IF(F11="","",F11*'Exchange Rate'!$B$5) | H11: =IF(L11="Inactive",0,IF(ISNUMBER(G11)*ISNUMBER(D11),IF(G11>D11,G11-D11,0),0)) -> 0 | I11: =IF(L11="Inactive",0,IF(ISNUMBER(F11)*ISNUMBER(E11),IF(F11>E11,F11-E11,0),0)) -> 0 | J11: =IF(L11="Inactive",0,IF(ISNUMBER(D11)*ISNUMBER(G11),IF(D11>G11,D11-G11,0),0)) -> 0 | K11: =IF(L11="Inactive",0,IF(ISNUMBER(E11)*ISNUMBER(F11),IF(E11>F11,E11-F11,0),0)) -> 0 | L11: Active | M11: =IF(A11="","—",A11&" ("&TEXT(B11,"MM/DD/YYYY")&")") -> —
C12: =IF(B12="","",TEXT(B12,"mmmm")) | E12: =IF(D12="","",D12*'Exchange Rate'!$E$5) | G12: =IF(F12="","",F12*'Exchange Rate'!$B$5) | H12: =IF(L12="Inactive",0,IF(ISNUMBER(G12)*ISNUMBER(D12),IF(G12>D12,G12-D12,0),0)) -> 0 | I12: =IF(L12="Inactive",0,IF(ISNUMBER(F12)*ISNUMBER(E12),IF(F12>E12,F12-E12,0),0)) -> 0 | J12: =IF(L12="Inactive",0,IF(ISNUMBER(D12)*ISNUMBER(G12),IF(D12>G12,D12-G12,0),0)) -> 0 | K12: =IF(L12="Inactive",0,IF(ISNUMBER(E12)*ISNUMBER(F12),IF(E12>F12,E12-F12,0),0)) -> 0 | L12: Active | M12: =IF(A12="","—",A12&" ("&TEXT(B12,"MM/DD/YYYY")&")") -> —
C13: =IF(B13="","",TEXT(B13,"mmmm")) | E13: =IF(D13="","",D13*'Exchange Rate'!$E$5) | G13: =IF(F13="","",F13*'Exchange Rate'!$B$5) | H13: =IF(L13="Inactive",0,IF(ISNUMBER(G13)*ISNUMBER(D13),IF(G13>D13,G13-D13,0),0)) -> 0 | I13: =IF(L13="Inactive",0,IF(ISNUMBER(F13)*ISNUMBER(E13),IF(F13>E13,F13-E13,0),0)) -> 0 | J13: =IF(L13="Inactive",0,IF(ISNUMBER(D13)*ISNUMBER(G13),IF(D13>G13,D13-G13,0),0)) -> 0 | K13: =IF(L13="Inactive",0,IF(ISNUMBER(E13)*ISNUMBER(F13),IF(E13>F13,E13-F13,0),0)) -> 0 | L13: Active | M13: =IF(A13="","—",A13&" ("&TEXT(B13,"MM/DD/YYYY")&")") -> —
C14: =IF(B14="","",TEXT(B14,"mmmm")) | E14: =IF(D14="","",D14*'Exchange Rate'!$E$5) | G14: =IF(F14="","",F14*'Exchange Rate'!$B$5) | H14: =IF(L14="Inactive",0,IF(ISNUMBER(G14)*ISNUMBER(D14),IF(G14>D14,G14-D14,0),0)) -> 0 | I14: =IF(L14="Inactive",0,IF(ISNUMBER(F14)*ISNUMBER(E14),IF(F14>E14,F14-E14,0),0)) -> 0 | J14: =IF(L14="Inactive",0,IF(ISNUMBER(D14)*ISNUMBER(G14),IF(D14>G14,D14-G14,0),0)) -> 0 | K14: =IF(L14="Inactive",0,IF(ISNUMBER(E14)*ISNUMBER(F14),IF(E14>F14,E14-F14,0),0)) -> 0 | L14: Active | M14: =IF(A14="","—",A14&" ("&TEXT(B14,"MM/DD/YYYY")&")") -> —
C15: =IF(B15="","",TEXT(B15,"mmmm")) | E15: =IF(D15="","",D15*'Exchange Rate'!$E$5) | G15: =IF(F15="","",F15*'Exchange Rate'!$B$5) | H15: =IF(L15="Inactive",0,IF(ISNUMBER(G15)*ISNUMBER(D15),IF(G15>D15,G15-D15,0),0)) -> 0 | I15: =IF(L15="Inactive",0,IF(ISNUMBER(F15)*ISNUMBER(E15),IF(F15>E15,F15-E15,0),0)) -> 0 | J15: =IF(L15="Inactive",0,IF(ISNUMBER(D15)*ISNUMBER(G15),IF(D15>G15,D15-G15,0),0)) -> 0 | K15: =IF(L15="Inactive",0,IF(ISNUMBER(E15)*ISNUMBER(F15),IF(E15>F15,E15-F15,0),0)) -> 0 | L15: Active | M15: =IF(A15="","—",A15&" ("&TEXT(B15,"MM/DD/YYYY")&")") -> —
C16: =IF(B16="","",TEXT(B16,"mmmm")) | E16: =IF(D16="","",D16*'Exchange Rate'!$E$5) | G16: =IF(F16="","",F16*'Exchange Rate'!$B$5) | H16: =IF(L16="Inactive",0,IF(ISNUMBER(G16)*ISNUMBER(D16),IF(G16>D16,G16-D16,0),0)) -> 0 | I16: =IF(L16="Inactive",0,IF(ISNUMBER(F16)*ISNUMBER(E16),IF(F16>E16,F16-E16,0),0)) -> 0 | J16: =IF(L16="Inactive",0,IF(ISNUMBER(D16)*ISNUMBER(G16),IF(D16>G16,D16-G16,0),0)) -> 0 | K16: =IF(L16="Inactive",0,IF(ISNUMBER(E16)*ISNUMBER(F16),IF(E16>F16,E16-F16,0),0)) -> 0 | L16: Active | M16: =IF(A16="","—",A16&" ("&TEXT(B16,"MM/DD/YYYY")&")") -> —
C17: =IF(B17="","",TEXT(B17,"mmmm")) | E17: =IF(D17="","",D17*'Exchange Rate'!$E$5) | G17: =IF(F17="","",F17*'Exchange Rate'!$B$5) | H17: =IF(L17="Inactive",0,IF(ISNUMBER(G17)*ISNUMBER(D17),IF(G17>D17,G17-D17,0),0)) -> 0 | I17: =IF(L17="Inactive",0,IF(ISNUMBER(F17)*ISNUMBER(E17),IF(F17>E17,F17-E17,0),0)) -> 0 | J17: =IF(L17="Inactive",0,IF(ISNUMBER(D17)*ISNUMBER(G17),IF(D17>G17,D17-G17,0),0)) -> 0 | K17: =IF(L17="Inactive",0,IF(ISNUMBER(E17)*ISNUMBER(F17),IF(E17>F17,E17-F17,0),0)) -> 0 | L17: Active | M17: =IF(A17="","—",A17&" ("&TEXT(B17,"MM/DD/YYYY")&")") -> —
C18: =IF(B18="","",TEXT(B18,"mmmm")) | E18: =IF(D18="","",D18*'Exchange Rate'!$E$5) | G18: =IF(F18="","",F18*'Exchange Rate'!$B$5) | H18: =IF(L18="Inactive",0,IF(ISNUMBER(G18)*ISNUMBER(D18),IF(G18>D18,G18-D18,0),0)) -> 0 | I18: =IF(L18="Inactive",0,IF(ISNUMBER(F18)*ISNUMBER(E18),IF(F18>E18,F18-E18,0),0)) -> 0 | J18: =IF(L18="Inactive",0,IF(ISNUMBER(D18)*ISNUMBER(G18),IF(D18>G18,D18-G18,0),0)) -> 0 | K18: =IF(L18="Inactive",0,IF(ISNUMBER(E18)*ISNUMBER(F18),IF(E18>F18,E18-F18,0),0)) -> 0 | L18: Active | M18: =IF(A18="","—",A18&" ("&TEXT(B18,"MM/DD/YYYY")&")") -> —
C19: =IF(B19="","",TEXT(B19,"mmmm")) | E19: =IF(D19="","",D19*'Exchange Rate'!$E$5) | G19: =IF(F19="","",F19*'Exchange Rate'!$B$5) | H19: =IF(L19="Inactive",0,IF(ISNUMBER(G19)*ISNUMBER(D19),IF(G19>D19,G19-D19,0),0)) -> 0 | I19: =IF(L19="Inactive",0,IF(ISNUMBER(F19)*ISNUMBER(E19),IF(F19>E19,F19-E19,0),0)) -> 0 | J19: =IF(L19="Inactive",0,IF(ISNUMBER(D19)*ISNUMBER(G19),IF(D19>G19,D19-G19,0),0)) -> 0 | K19: =IF(L19="Inactive",0,IF(ISNUMBER(E19)*ISNUMBER(F19),IF(E19>F19,E19-F19,0),0)) -> 0 | L19: Active | M19: =IF(A19="","—",A19&" ("&TEXT(B19,"MM/DD/YYYY")&")") -> —
... C107: =IF(B107="","",TEXT(B107,"mmmm")) | E107: =IF(D107="","",D107*'Exchange Rate'!$E$5) | G107: =IF(F107="","",F107*'Exchange Rate'!$B$5) | H107: =IF(L107="Inactive",0,IF(ISNUMBER(G107)*ISNUMBER(D107),IF(G107>D107,G107-D107,0),0)) -> 0 | I107: =IF(L107="Inactive",0,IF(ISNUMBER(F107)*ISNUMBER(E107),IF(F107>E107,F107-E107,0),0)) -> 0 | J107: =IF(L107="Inactive",0,IF(ISNUMBER(D107)*ISNUMBER(G107),IF(D107>G107,D107-G107,0),0)) -> 0 | K107: =IF(L107="Inactive",0,IF(ISNUMBER(E107)*ISNUMBER(F107),IF(E107>F107,E107-F107,0),0)) -> 0 | L107: Active | M107: =IF(A107="","—",A107&" ("&TEXT(B107,"MM/DD/YYYY")&")") -> —
A108: TOTAL CATEGORY VALUE | D108: =SUM(D8:D107) -> 0 | E108: =SUM(E8:E107) -> 0 | F108: =SUM(F8:F107) -> 0 | G108: =SUM(G8:G107) -> 0 | H108: =SUM(H8:H107) -> 0 | I108: =SUM(I8:I107) -> 0 | J108: =SUM(J8:J107) -> 0 | K108: =SUM(K8:K107) -> 0 | L108: =SUM(L8:L107) -> 0
A110: 📋 USER GUIDE & OPERATIONAL INSTRUCTIONS
A111: Step 1 — DATA ENTRY
A112: Input rows sequentially. Type directly into Col D (Purchase JPY) and Col F (Selling PHP) ONLY. All other columns auto-calculate. Yellow cells = manual entry. White cells = formulas.
A113: Step 2 — DUPLICATE IDs
A114: If tracking duplicate items, check the QUICK-VIEW bar (Row 5). A ⚠️ alert fires when the same Product ID appears more than once. Use the 'Date of Entry' (Col B) timestamp in the lookup to immediately distinguish which entry is which.
A115: Step 3 — ANALYTICS FILTER
A116: Toggle the Analytics view on the '9. Overall Analytics' sheet using the timeframe filter (D2) to review Weekly, Monthly, or Annual financial health variations.
A117: Step 4 — EXCHANGE RATES
A118: Never manually edit currency columns. To update rates, go to the 'Exchange Rate' sheet and edit ONLY cells B5 (PHP→JPY) or E5 (JPY→PHP). All values across the workbook update instantly.
A119: Step 5 — STOCK STATUS
A120: Use Column L dropdown (Active/Inactive) to toggle items. Inactive rows contribute ZERO to profit, loss, and analytics totals — ideal for recalled, damaged, or discontinued stock.

Sheet 5. On hand orders PHP
A1: KEN JP ANIME FIGURES SHOP
A4: 📦 5. ON HAND ORDERS PHP | Rates: 'Exchange Rate'!B5 (PHP→JPY) & E5 (JPY→PHP)
A5: 🔍 FUZZY SEARCH | B5: ⬇ type partial name or ID: | D5: =IF($C$5="","← type above",IFERROR(ROWS(filter($M$8:$M$107,ISNUMBER(SEARCH($C$5,$M$8:$M$107))))&" match(es) found","❌ 0 found")) -> ← type above | E5: View match #: | F5: 1 | G5: =IF($C$5="","— no active search —",IFERROR(INDEX(filter($M$8:$M$107,ISNUMBER(SEARCH($C$5,$M$8:$M$107)),"❌ No Data Found"),VALUE($F$5)),"❌ No Data Found")) -> — no active search — | H5: =IFERROR(IF($G$5="❌ No Data Found","—",IF($G$5="— no active search —","—",INDEX($D$8:$D$107,MATCH($G$5,$M$8:$M$107,0)))),"—") -> — | I5: =IFERROR(IF($G$5="❌ No Data Found","—",IF($G$5="— no active search —","—",INDEX($F$8:$F$107,MATCH($G$5,$M$8:$M$107,0)))),"—") -> — | J5: =IFERROR(IF($G$5="❌ No Data Found","—",IF($G$5="— no active search —","—",INDEX($H$8:$H$107,MATCH($G$5,$M$8:$M$107,0)))),"—") -> — | K5: =IFERROR(IF($G$5="❌ No Data Found","—",IF($G$5="— no active search —","—",INDEX($J$8:$J$107,MATCH($G$5,$M$8:$M$107,0)))),"—") -> — | L5: =IFERROR(IF($G$5="❌ No Data Found","—",IF($G$5="— no active search —","—",INDEX($L$8:$L$107,MATCH($G$5,$M$8:$M$107,0)))),"—") -> —
A7: Product ID | B7: Date of Entry | C7: Transaction Month | D7: Purchase Price (JPY) | E7: Purchase Price (PHP) | F7: Selling Price (PHP) | G7: Selling Price (JPY) | H7: Net Profit (JPY) | I7: Net Profit (PHP) | J7: Net Loss (JPY) | K7: Net Loss (PHP) | L7: Stock Status | M7: SEARCH_KEY (hidden)
C8: =IF(B8="","",TEXT(B8,"mmmm")) | E8: =IF(D8="","",D8*'Exchange Rate'!$E$5) | G8: =IF(F8="","",F8*'Exchange Rate'!$B$5) | H8: =IF(L8="Inactive",0,IF(ISNUMBER(G8)*ISNUMBER(D8),IF(G8>D8,G8-D8,0),0)) -> 0 | I8: =IF(L8="Inactive",0,IF(ISNUMBER(F8)*ISNUMBER(E8),IF(F8>E8,F8-E8,0),0)) -> 0 | J8: =IF(L8="Inactive",0,IF(ISNUMBER(D8)*ISNUMBER(G8),IF(D8>G8,D8-G8,0),0)) -> 0 | K8: =IF(L8="Inactive",0,IF(ISNUMBER(E8)*ISNUMBER(F8),IF(E8>F8,E8-F8,0),0)) -> 0 | L8: Active | M8: =IF(A8="","—",A8&" ("&TEXT(B8,"MM/DD/YYYY")&")") -> —
C9: =IF(B9="","",TEXT(B9,"mmmm")) | E9: =IF(D9="","",D9*'Exchange Rate'!$E$5) | G9: =IF(F9="","",F9*'Exchange Rate'!$B$5) | H9: =IF(L9="Inactive",0,IF(ISNUMBER(G9)*ISNUMBER(D9),IF(G9>D9,G9-D9,0),0)) -> 0 | I9: =IF(L9="Inactive",0,IF(ISNUMBER(F9)*ISNUMBER(E9),IF(F9>E9,F9-E9,0),0)) -> 0 | J9: =IF(L9="Inactive",0,IF(ISNUMBER(D9)*ISNUMBER(G9),IF(D9>G9,D9-G9,0),0)) -> 0 | K9: =IF(L9="Inactive",0,IF(ISNUMBER(E9)*ISNUMBER(F9),IF(E9>F9,E9-F9,0),0)) -> 0 | L9: Active | M9: =IF(A9="","—",A9&" ("&TEXT(B9,"MM/DD/YYYY")&")") -> —
C10: =IF(B10="","",TEXT(B10,"mmmm")) | E10: =IF(D10="","",D10*'Exchange Rate'!$E$5) | G10: =IF(F10="","",F10*'Exchange Rate'!$B$5) | H10: =IF(L10="Inactive",0,IF(ISNUMBER(G10)*ISNUMBER(D10),IF(G10>D10,G10-D10,0),0)) -> 0 | I10: =IF(L10="Inactive",0,IF(ISNUMBER(F10)*ISNUMBER(E10),IF(F10>E10,F10-E10,0),0)) -> 0 | J10: =IF(L10="Inactive",0,IF(ISNUMBER(D10)*ISNUMBER(G10),IF(D10>G10,D10-G10,0),0)) -> 0 | K10: =IF(L10="Inactive",0,IF(ISNUMBER(E10)*ISNUMBER(F10),IF(E10>F10,E10-F10,0),0)) -> 0 | L10: Active | M10: =IF(A10="","—",A10&" ("&TEXT(B10,"MM/DD/YYYY")&")") -> —
C11: =IF(B11="","",TEXT(B11,"mmmm")) | E11: =IF(D11="","",D11*'Exchange Rate'!$E$5) | G11: =IF(F11="","",F11*'Exchange Rate'!$B$5) | H11: =IF(L11="Inactive",0,IF(ISNUMBER(G11)*ISNUMBER(D11),IF(G11>D11,G11-D11,0),0)) -> 0 | I11: =IF(L11="Inactive",0,IF(ISNUMBER(F11)*ISNUMBER(E11),IF(F11>E11,F11-E11,0),0)) -> 0 | J11: =IF(L11="Inactive",0,IF(ISNUMBER(D11)*ISNUMBER(G11),IF(D11>G11,D11-G11,0),0)) -> 0 | K11: =IF(L11="Inactive",0,IF(ISNUMBER(E11)*ISNUMBER(F11),IF(E11>F11,E11-F11,0),0)) -> 0 | L11: Active | M11: =IF(A11="","—",A11&" ("&TEXT(B11,"MM/DD/YYYY")&")") -> —
C12: =IF(B12="","",TEXT(B12,"mmmm")) | E12: =IF(D12="","",D12*'Exchange Rate'!$E$5) | G12: =IF(F12="","",F12*'Exchange Rate'!$B$5) | H12: =IF(L12="Inactive",0,IF(ISNUMBER(G12)*ISNUMBER(D12),IF(G12>D12,G12-D12,0),0)) -> 0 | I12: =IF(L12="Inactive",0,IF(ISNUMBER(F12)*ISNUMBER(E12),IF(F12>E12,F12-E12,0),0)) -> 0 | J12: =IF(L12="Inactive",0,IF(ISNUMBER(D12)*ISNUMBER(G12),IF(D12>G12,D12-G12,0),0)) -> 0 | K12: =IF(L12="Inactive",0,IF(ISNUMBER(E12)*ISNUMBER(F12),IF(E12>F12,E12-F12,0),0)) -> 0 | L12: Active | M12: =IF(A12="","—",A12&" ("&TEXT(B12,"MM/DD/YYYY")&")") -> —
C13: =IF(B13="","",TEXT(B13,"mmmm")) | E13: =IF(D13="","",D13*'Exchange Rate'!$E$5) | G13: =IF(F13="","",F13*'Exchange Rate'!$B$5) | H13: =IF(L13="Inactive",0,IF(ISNUMBER(G13)*ISNUMBER(D13),IF(G13>D13,G13-D13,0),0)) -> 0 | I13: =IF(L13="Inactive",0,IF(ISNUMBER(F13)*ISNUMBER(E13),IF(F13>E13,F13-E13,0),0)) -> 0 | J13: =IF(L13="Inactive",0,IF(ISNUMBER(D13)*ISNUMBER(G13),IF(D13>G13,D13-G13,0),0)) -> 0 | K13: =IF(L13="Inactive",0,IF(ISNUMBER(E13)*ISNUMBER(F13),IF(E13>F13,E13-F13,0),0)) -> 0 | L13: Active | M13: =IF(A13="","—",A13&" ("&TEXT(B13,"MM/DD/YYYY")&")") -> —
C14: =IF(B14="","",TEXT(B14,"mmmm")) | E14: =IF(D14="","",D14*'Exchange Rate'!$E$5) | G14: =IF(F14="","",F14*'Exchange Rate'!$B$5) | H14: =IF(L14="Inactive",0,IF(ISNUMBER(G14)*ISNUMBER(D14),IF(G14>D14,G14-D14,0),0)) -> 0 | I14: =IF(L14="Inactive",0,IF(ISNUMBER(F14)*ISNUMBER(E14),IF(F14>E14,F14-E14,0),0)) -> 0 | J14: =IF(L14="Inactive",0,IF(ISNUMBER(D14)*ISNUMBER(G14),IF(D14>G14,D14-G14,0),0)) -> 0 | K14: =IF(L14="Inactive",0,IF(ISNUMBER(E14)*ISNUMBER(F14),IF(E14>F14,E14-F14,0),0)) -> 0 | L14: Active | M14: =IF(A14="","—",A14&" ("&TEXT(B14,"MM/DD/YYYY")&")") -> —
C15: =IF(B15="","",TEXT(B15,"mmmm")) | E15: =IF(D15="","",D15*'Exchange Rate'!$E$5) | G15: =IF(F15="","",F15*'Exchange Rate'!$B$5) | H15: =IF(L15="Inactive",0,IF(ISNUMBER(G15)*ISNUMBER(D15),IF(G15>D15,G15-D15,0),0)) -> 0 | I15: =IF(L15="Inactive",0,IF(ISNUMBER(F15)*ISNUMBER(E15),IF(F15>E15,F15-E15,0),0)) -> 0 | J15: =IF(L15="Inactive",0,IF(ISNUMBER(D15)*ISNUMBER(G15),IF(D15>G15,D15-G15,0),0)) -> 0 | K15: =IF(L15="Inactive",0,IF(ISNUMBER(E15)*ISNUMBER(F15),IF(E15>F15,E15-F15,0),0)) -> 0 | L15: Active | M15: =IF(A15="","—",A15&" ("&TEXT(B15,"MM/DD/YYYY")&")") -> —
C16: =IF(B16="","",TEXT(B16,"mmmm")) | E16: =IF(D16="","",D16*'Exchange Rate'!$E$5) | G16: =IF(F16="","",F16*'Exchange Rate'!$B$5) | H16: =IF(L16="Inactive",0,IF(ISNUMBER(G16)*ISNUMBER(D16),IF(G16>D16,G16-D16,0),0)) -> 0 | I16: =IF(L16="Inactive",0,IF(ISNUMBER(F16)*ISNUMBER(E16),IF(F16>E16,F16-E16,0),0)) -> 0 | J16: =IF(L16="Inactive",0,IF(ISNUMBER(D16)*ISNUMBER(G16),IF(D16>G16,D16-G16,0),0)) -> 0 | K16: =IF(L16="Inactive",0,IF(ISNUMBER(E16)*ISNUMBER(F16),IF(E16>F16,E16-F16,0),0)) -> 0 | L16: Active | M16: =IF(A16="","—",A16&" ("&TEXT(B16,"MM/DD/YYYY")&")") -> —
C17: =IF(B17="","",TEXT(B17,"mmmm")) | E17: =IF(D17="","",D17*'Exchange Rate'!$E$5) | G17: =IF(F17="","",F17*'Exchange Rate'!$B$5) | H17: =IF(L17="Inactive",0,IF(ISNUMBER(G17)*ISNUMBER(D17),IF(G17>D17,G17-D17,0),0)) -> 0 | I17: =IF(L17="Inactive",0,IF(ISNUMBER(F17)*ISNUMBER(E17),IF(F17>E17,F17-E17,0),0)) -> 0 | J17: =IF(L17="Inactive",0,IF(ISNUMBER(D17)*ISNUMBER(G17),IF(D17>G17,D17-G17,0),0)) -> 0 | K17: =IF(L17="Inactive",0,IF(ISNUMBER(E17)*ISNUMBER(F17),IF(E17>F17,E17-F17,0),0)) -> 0 | L17: Active | M17: =IF(A17="","—",A17&" ("&TEXT(B17,"MM/DD/YYYY")&")") -> —
C18: =IF(B18="","",TEXT(B18,"mmmm")) | E18: =IF(D18="","",D18*'Exchange Rate'!$E$5) | G18: =IF(F18="","",F18*'Exchange Rate'!$B$5) | H18: =IF(L18="Inactive",0,IF(ISNUMBER(G18)*ISNUMBER(D18),IF(G18>D18,G18-D18,0),0)) -> 0 | I18: =IF(L18="Inactive",0,IF(ISNUMBER(F18)*ISNUMBER(E18),IF(F18>E18,F18-E18,0),0)) -> 0 | J18: =IF(L18="Inactive",0,IF(ISNUMBER(D18)*ISNUMBER(G18),IF(D18>G18,D18-G18,0),0)) -> 0 | K18: =IF(L18="Inactive",0,IF(ISNUMBER(E18)*ISNUMBER(F18),IF(E18>F18,E18-F18,0),0)) -> 0 | L18: Active | M18: =IF(A18="","—",A18&" ("&TEXT(B18,"MM/DD/YYYY")&")") -> —
C19: =IF(B19="","",TEXT(B19,"mmmm")) | E19: =IF(D19="","",D19*'Exchange Rate'!$E$5) | G19: =IF(F19="","",F19*'Exchange Rate'!$B$5) | H19: =IF(L19="Inactive",0,IF(ISNUMBER(G19)*ISNUMBER(D19),IF(G19>D19,G19-D19,0),0)) -> 0 | I19: =IF(L19="Inactive",0,IF(ISNUMBER(F19)*ISNUMBER(E19),IF(F19>E19,F19-E19,0),0)) -> 0 | J19: =IF(L19="Inactive",0,IF(ISNUMBER(D19)*ISNUMBER(G19),IF(D19>G19,D19-G19,0),0)) -> 0 | K19: =IF(L19="Inactive",0,IF(ISNUMBER(E19)*ISNUMBER(F19),IF(E19>F19,E19-F19,0),0)) -> 0 | L19: Active | M19: =IF(A19="","—",A19&" ("&TEXT(B19,"MM/DD/YYYY")&")") -> —
... C107: =IF(B107="","",TEXT(B107,"mmmm")) | E107: =IF(D107="","",D107*'Exchange Rate'!$E$5) | G107: =IF(F107="","",F107*'Exchange Rate'!$B$5) | H107: =IF(L107="Inactive",0,IF(ISNUMBER(G107)*ISNUMBER(D107),IF(G107>D107,G107-D107,0),0)) -> 0 | I107: =IF(L107="Inactive",0,IF(ISNUMBER(F107)*ISNUMBER(E107),IF(F107>E107,F107-E107,0),0)) -> 0 | J107: =IF(L107="Inactive",0,IF(ISNUMBER(D107)*ISNUMBER(G107),IF(D107>G107,D107-G107,0),0)) -> 0 | K107: =IF(L107="Inactive",0,IF(ISNUMBER(E107)*ISNUMBER(F107),IF(E107>F107,E107-F107,0),0)) -> 0 | L107: Active | M107: =IF(A107="","—",A107&" ("&TEXT(B107,"MM/DD/YYYY")&")") -> —
A108: TOTAL CATEGORY VALUE | D108: =SUM(D8:D107) -> 0 | E108: =SUM(E8:E107) -> 0 | F108: =SUM(F8:F107) -> 0 | G108: =SUM(G8:G107) -> 0 | H108: =SUM(H8:H107) -> 0 | I108: =SUM(I8:I107) -> 0 | J108: =SUM(J8:J107) -> 0 | K108: =SUM(K8:K107) -> 0 | L108: =SUM(L8:L107) -> 0
A110: 📋 USER GUIDE & OPERATIONAL INSTRUCTIONS
A111: Step 1 — DATA ENTRY
A112: Input rows sequentially. Type directly into Col D (Purchase JPY) and Col F (Selling PHP) ONLY. All other columns auto-calculate. Yellow cells = manual entry. White cells = formulas.
A113: Step 2 — DUPLICATE IDs
A114: If tracking duplicate items, check the QUICK-VIEW bar (Row 5). A ⚠️ alert fires when the same Product ID appears more than once. Use the 'Date of Entry' (Col B) timestamp in the lookup to immediately distinguish which entry is which.
A115: Step 3 — ANALYTICS FILTER
A116: Toggle the Analytics view on the '9. Overall Analytics' sheet using the timeframe filter (D2) to review Weekly, Monthly, or Annual financial health variations.
A117: Step 4 — EXCHANGE RATES
A118: Never manually edit currency columns. To update rates, go to the 'Exchange Rate' sheet and edit ONLY cells B5 (PHP→JPY) or E5 (JPY→PHP). All values across the workbook update instantly.
A119: Step 5 — STOCK STATUS
A120: Use Column L dropdown (Active/Inactive) to toggle items. Inactive rows contribute ZERO to profit, loss, and analytics totals — ideal for recalled, damaged, or discontinued stock.

Sheet 6. Pre Orders
A1: KEN JP ANIME FIGURES SHOP
A4: 📦 6. PRE ORDERS | Rates: 'Exchange Rate'!B5 (PHP→JPY) & E5 (JPY→PHP)
A5: 🔍 FUZZY SEARCH | B5: ⬇ type partial name or ID: | D5: =IF($C$5="","← type above",IFERROR(ROWS(filter($M$8:$M$107,ISNUMBER(SEARCH($C$5,$M$8:$M$107))))&" match(es) found","❌ 0 found")) -> ← type above | E5: View match #: | F5: 1 | G5: =IF($C$5="","— no active search —",IFERROR(INDEX(filter($M$8:$M$107,ISNUMBER(SEARCH($C$5,$M$8:$M$107)),"❌ No Data Found"),VALUE($F$5)),"❌ No Data Found")) -> — no active search — | H5: =IFERROR(IF($G$5="❌ No Data Found","—",IF($G$5="— no active search —","—",INDEX($D$8:$D$107,MATCH($G$5,$M$8:$M$107,0)))),"—") -> — | I5: =IFERROR(IF($G$5="❌ No Data Found","—",IF($G$5="— no active search —","—",INDEX($F$8:$F$107,MATCH($G$5,$M$8:$M$107,0)))),"—") -> — | J5: =IFERROR(IF($G$5="❌ No Data Found","—",IF($G$5="— no active search —","—",INDEX($H$8:$H$107,MATCH($G$5,$M$8:$M$107,0)))),"—") -> — | K5: =IFERROR(IF($G$5="❌ No Data Found","—",IF($G$5="— no active search —","—",INDEX($J$8:$J$107,MATCH($G$5,$M$8:$M$107,0)))),"—") -> — | L5: =IFERROR(IF($G$5="❌ No Data Found","—",IF($G$5="— no active search —","—",INDEX($L$8:$L$107,MATCH($G$5,$M$8:$M$107,0)))),"—") -> —
A7: Product ID | B7: Date of Entry | C7: Transaction Month | D7: Purchase Price (JPY) | E7: Purchase Price (PHP) | F7: Selling Price (PHP) | G7: Selling Price (JPY) | H7: Net Profit (JPY) | I7: Net Profit (PHP) | J7: Net Loss (JPY) | K7: Net Loss (PHP) | L7: Stock Status | M7: SEARCH_KEY (hidden)
C8: =IF(B8="","",TEXT(B8,"mmmm")) | E8: =IF(D8="","",D8*'Exchange Rate'!$E$5) | G8: =IF(F8="","",F8*'Exchange Rate'!$B$5) | H8: =IF(L8="Inactive",0,IF(ISNUMBER(G8)*ISNUMBER(D8),IF(G8>D8,G8-D8,0),0)) -> 0 | I8: =IF(L8="Inactive",0,IF(ISNUMBER(F8)*ISNUMBER(E8),IF(F8>E8,F8-E8,0),0)) -> 0 | J8: =IF(L8="Inactive",0,IF(ISNUMBER(D8)*ISNUMBER(G8),IF(D8>G8,D8-G8,0),0)) -> 0 | K8: =IF(L8="Inactive",0,IF(ISNUMBER(E8)*ISNUMBER(F8),IF(E8>F8,E8-F8,0),0)) -> 0 | L8: Active | M8: =IF(A8="","—",A8&" ("&TEXT(B8,"MM/DD/YYYY")&")") -> —
C9: =IF(B9="","",TEXT(B9,"mmmm")) | E9: =IF(D9="","",D9*'Exchange Rate'!$E$5) | G9: =IF(F9="","",F9*'Exchange Rate'!$B$5) | H9: =IF(L9="Inactive",0,IF(ISNUMBER(G9)*ISNUMBER(D9),IF(G9>D9,G9-D9,0),0)) -> 0 | I9: =IF(L9="Inactive",0,IF(ISNUMBER(F9)*ISNUMBER(E9),IF(F9>E9,F9-E9,0),0)) -> 0 | J9: =IF(L9="Inactive",0,IF(ISNUMBER(D9)*ISNUMBER(G9),IF(D9>G9,D9-G9,0),0)) -> 0 | K9: =IF(L9="Inactive",0,IF(ISNUMBER(E9)*ISNUMBER(F9),IF(E9>F9,E9-F9,0),0)) -> 0 | L9: Active | M9: =IF(A9="","—",A9&" ("&TEXT(B9,"MM/DD/YYYY")&")") -> —
C10: =IF(B10="","",TEXT(B10,"mmmm")) | E10: =IF(D10="","",D10*'Exchange Rate'!$E$5) | G10: =IF(F10="","",F10*'Exchange Rate'!$B$5) | H10: =IF(L10="Inactive",0,IF(ISNUMBER(G10)*ISNUMBER(D10),IF(G10>D10,G10-D10,0),0)) -> 0 | I10: =IF(L10="Inactive",0,IF(ISNUMBER(F10)*ISNUMBER(E10),IF(F10>E10,F10-E10,0),0)) -> 0 | J10: =IF(L10="Inactive",0,IF(ISNUMBER(D10)*ISNUMBER(G10),IF(D10>G10,D10-G10,0),0)) -> 0 | K10: =IF(L10="Inactive",0,IF(ISNUMBER(E10)*ISNUMBER(F10),IF(E10>F10,E10-F10,0),0)) -> 0 | L10: Active | M10: =IF(A10="","—",A10&" ("&TEXT(B10,"MM/DD/YYYY")&")") -> —
C11: =IF(B11="","",TEXT(B11,"mmmm")) | E11: =IF(D11="","",D11*'Exchange Rate'!$E$5) | G11: =IF(F11="","",F11*'Exchange Rate'!$B$5) | H11: =IF(L11="Inactive",0,IF(ISNUMBER(G11)*ISNUMBER(D11),IF(G11>D11,G11-D11,0),0)) -> 0 | I11: =IF(L11="Inactive",0,IF(ISNUMBER(F11)*ISNUMBER(E11),IF(F11>E11,F11-E11,0),0)) -> 0 | J11: =IF(L11="Inactive",0,IF(ISNUMBER(D11)*ISNUMBER(G11),IF(D11>G11,D11-G11,0),0)) -> 0 | K11: =IF(L11="Inactive",0,IF(ISNUMBER(E11)*ISNUMBER(F11),IF(E11>F11,E11-F11,0),0)) -> 0 | L11: Active | M11: =IF(A11="","—",A11&" ("&TEXT(B11,"MM/DD/YYYY")&")") -> —
C12: =IF(B12="","",TEXT(B12,"mmmm")) | E12: =IF(D12="","",D12*'Exchange Rate'!$E$5) | G12: =IF(F12="","",F12*'Exchange Rate'!$B$5) | H12: =IF(L12="Inactive",0,IF(ISNUMBER(G12)*ISNUMBER(D12),IF(G12>D12,G12-D12,0),0)) -> 0 | I12: =IF(L12="Inactive",0,IF(ISNUMBER(F12)*ISNUMBER(E12),IF(F12>E12,F12-E12,0),0)) -> 0 | J12: =IF(L12="Inactive",0,IF(ISNUMBER(D12)*ISNUMBER(G12),IF(D12>G12,D12-G12,0),0)) -> 0 | K12: =IF(L12="Inactive",0,IF(ISNUMBER(E12)*ISNUMBER(F12),IF(E12>F12,E12-F12,0),0)) -> 0 | L12: Active | M12: =IF(A12="","—",A12&" ("&TEXT(B12,"MM/DD/YYYY")&")") -> —
C13: =IF(B13="","",TEXT(B13,"mmmm")) | E13: =IF(D13="","",D13*'Exchange Rate'!$E$5) | G13: =IF(F13="","",F13*'Exchange Rate'!$B$5) | H13: =IF(L13="Inactive",0,IF(ISNUMBER(G13)*ISNUMBER(D13),IF(G13>D13,G13-D13,0),0)) -> 0 | I13: =IF(L13="Inactive",0,IF(ISNUMBER(F13)*ISNUMBER(E13),IF(F13>E13,F13-E13,0),0)) -> 0 | J13: =IF(L13="Inactive",0,IF(ISNUMBER(D13)*ISNUMBER(G13),IF(D13>G13,D13-G13,0),0)) -> 0 | K13: =IF(L13="Inactive",0,IF(ISNUMBER(E13)*ISNUMBER(F13),IF(E13>F13,E13-F13,0),0)) -> 0 | L13: Active | M13: =IF(A13="","—",A13&" ("&TEXT(B13,"MM/DD/YYYY")&")") -> —
C14: =IF(B14="","",TEXT(B14,"mmmm")) | E14: =IF(D14="","",D14*'Exchange Rate'!$E$5) | G14: =IF(F14="","",F14*'Exchange Rate'!$B$5) | H14: =IF(L14="Inactive",0,IF(ISNUMBER(G14)*ISNUMBER(D14),IF(G14>D14,G14-D14,0),0)) -> 0 | I14: =IF(L14="Inactive",0,IF(ISNUMBER(F14)*ISNUMBER(E14),IF(F14>E14,F14-E14,0),0)) -> 0 | J14: =IF(L14="Inactive",0,IF(ISNUMBER(D14)*ISNUMBER(G14),IF(D14>G14,D14-G14,0),0)) -> 0 | K14: =IF(L14="Inactive",0,IF(ISNUMBER(E14)*ISNUMBER(F14),IF(E14>F14,E14-F14,0),0)) -> 0 | L14: Active | M14: =IF(A14="","—",A14&" ("&TEXT(B14,"MM/DD/YYYY")&")") -> —
C15: =IF(B15="","",TEXT(B15,"mmmm")) | E15: =IF(D15="","",D15*'Exchange Rate'!$E$5) | G15: =IF(F15="","",F15*'Exchange Rate'!$B$5) | H15: =IF(L15="Inactive",0,IF(ISNUMBER(G15)*ISNUMBER(D15),IF(G15>D15,G15-D15,0),0)) -> 0 | I15: =IF(L15="Inactive",0,IF(ISNUMBER(F15)*ISNUMBER(E15),IF(F15>E15,F15-E15,0),0)) -> 0 | J15: =IF(L15="Inactive",0,IF(ISNUMBER(D15)*ISNUMBER(G15),IF(D15>G15,D15-G15,0),0)) -> 0 | K15: =IF(L15="Inactive",0,IF(ISNUMBER(E15)*ISNUMBER(F15),IF(E15>F15,E15-F15,0),0)) -> 0 | L15: Active | M15: =IF(A15="","—",A15&" ("&TEXT(B15,"MM/DD/YYYY")&")") -> —
C16: =IF(B16="","",TEXT(B16,"mmmm")) | E16: =IF(D16="","",D16*'Exchange Rate'!$E$5) | G16: =IF(F16="","",F16*'Exchange Rate'!$B$5) | H16: =IF(L16="Inactive",0,IF(ISNUMBER(G16)*ISNUMBER(D16),IF(G16>D16,G16-D16,0),0)) -> 0 | I16: =IF(L16="Inactive",0,IF(ISNUMBER(F16)*ISNUMBER(E16),IF(F16>E16,F16-E16,0),0)) -> 0 | J16: =IF(L16="Inactive",0,IF(ISNUMBER(D16)*ISNUMBER(G16),IF(D16>G16,D16-G16,0),0)) -> 0 | K16: =IF(L16="Inactive",0,IF(ISNUMBER(E16)*ISNUMBER(F16),IF(E16>F16,E16-F16,0),0)) -> 0 | L16: Active | M16: =IF(A16="","—",A16&" ("&TEXT(B16,"MM/DD/YYYY")&")") -> —
C17: =IF(B17="","",TEXT(B17,"mmmm")) | E17: =IF(D17="","",D17*'Exchange Rate'!$E$5) | G17: =IF(F17="","",F17*'Exchange Rate'!$B$5) | H17: =IF(L17="Inactive",0,IF(ISNUMBER(G17)*ISNUMBER(D17),IF(G17>D17,G17-D17,0),0)) -> 0 | I17: =IF(L17="Inactive",0,IF(ISNUMBER(F17)*ISNUMBER(E17),IF(F17>E17,F17-E17,0),0)) -> 0 | J17: =IF(L17="Inactive",0,IF(ISNUMBER(D17)*ISNUMBER(G17),IF(D17>G17,D17-G17,0),0)) -> 0 | K17: =IF(L17="Inactive",0,IF(ISNUMBER(E17)*ISNUMBER(F17),IF(E17>F17,E17-F17,0),0)) -> 0 | L17: Active | M17: =IF(A17="","—",A17&" ("&TEXT(B17,"MM/DD/YYYY")&")") -> —
